Workbook

Sheet Dashboard
A1: ZIP AHEAD: 26-28 Batch_Term-1
A2: A Structured Communication Development Program for PGDM Students
A3: 10 Weeks · 1 Submission / Week · 10 Total Submissions · Audio Based Delivery
A5: 📅 | B5: 🎙️ | C5: 📋 | D5: 📐 | E5: 📊 | F5: Total Groups: 15
A6: 10 Weeks | B6: 1 | C6: 10 | D6: 10 | E6: 5 | F6: Manu-7 | G6: Sandeep-8
A7: Programme Duration | B7: Sessions per Week | C7: Total Sessions | D7: Max Score / Session | E7: Assessment Areas | F7: Upto 10 Students per Group
E8: Assessment Framework
A9: Programme Overview | E9: Criterion | F9: Description | G9: Marks
A10: Delivery Mode | B10: Audio Submissions | E10: Clarity | F10: Clear confident opening with Pronunciation and Intonation; no filler | G10: 2
A11: Target Audience | B11: 26-28 Batch PGDM Students (any language level) | E11: Structure | F11: Logical flow: Situation → Action → Result | G11: 2
A12: Pedagogy | B12: Practice-Led: Build → Improve → Finalise | E12: Relevance | F12: Answer matches the question asked | G12: 2
A13: Response Length | B13: 30–60 seconds per audio submission | E13: Specificity | F13: Real examples, not generic claims | G13: 2
A14: Evaluation | B14: Rubric-based: 5 criteria × 2 marks each | E14: Completion | F14: Full response, no broken sentences | G14: 2
A15: Programme Lead | B15: L&D Team
E16: TOTAL | F16: Per Session Score | G16: 10
A18: Curriculum at a Glance
A19: Week | B19: Theme | C19: Focus Area | D19: Submission on Monday | E19: Trigger Email to be sent on Wednesday | F19: Trigger Email to be sent on Thursday | G19: Trigger Email to be sent on Friday
A20: Week 1 | B20: Self-Introduction | C20: Identity, domain, and role clarity | D20: 1
A21: Week 2 | B21: PGDM Rationale | C21: STAR-based task narration from internship | D21: 1
A22: Week 3 | B22: Strengths | C22: Evidence-backed strength with role impact | D22: 1
A23: Week 4 | B23: Weaknesses | C23: Honest weakness with growth narrative | D23: 1
A24: Week 5 | B24: Decision-Making | C24: Situation → Options → Decision logic | D24: 1
A25: Week 6 | B25: Skills & Career Goals | C25: Transferable skills and 5-year vision | D25: 1
A26: Week 7 | B26: Role Aspiration | C26: Target role fit, justification, positioning | D26: 1
A27: Week 8 | B27: Company & PGDM Rationale | C27: Company research and specialisation logic | D27: 1
A28: Week 9 | B28: Self-Introduction | C28: Identity, domain, and role clarity | D28: 1
A29: Week 10 | B29: Weaknesses | C29: Honest weakness with growth narrative | D29: 1

Sheet Curriculum
B1: ZIP AHEAD - Course Curriculum · Term-1: 10-Week Program
B2: A Structured Communication Development Program for 26-28 Batch PGDM Students
B4: Week | C4: Theme | D4: Day | E4: Question | F4: Instructions | G4: Coaching Focus | H4: Learning Outcome
B5: WEEK 1 - SELF-INTRODUCTION |
B6: W1 | C6: Self-Introduction | D6: Monday | E6: Introduce yourself in 1 minute? | F6: Tell us what you are studying and your domain. Begin with UG and include any projects that you have done. Do not talk about school or family. | G6: Clear opening sentence. No unnecessary filler. Domain stated confidently. | H6: Can begin answers clearly without confusion.
B7: WEEK 2 - PGDM Rationale |
B8: W2 | C8: PGDM Rationale | D8: Monday | E8: Why did you choose PGDM? | F8: Give your final answer in 45–60 seconds. Connect your past (undergrad or pre-PGDM experience) to your PGDM choice. | G8: How the degree bridged a skill gap. Genuine passion for the field. | H8: Can discuss specialisation with genuine rationale.
B9: WEEK 3 - STRENGTHS |
B10: W3 | C10: Strengths | D10: Monday | E10: What is your biggest strength? | F10: State one real strength. Give one short example where you used this strength. Avoid common words like 'hardworking' unless you prove it. | G10: Avoid generic words. Real example. Clear context. | H10: Can state strength with context.
B11: WEEK 4 - WEAKNESSES |
B12: W4 | C12: Weaknesses | D12: Monday | E12: What is your biggest weakness? | F12: State one real weakness you are working on. Do not give fake answers like 'I am a perfectionist.' Keep it honest and simple. | G12: Honest (not fake). Clear statement. No justification yet. | H12: Can acknowledge limitation.
B13: WEEK 5 - SKILL DEVELOPMENT |
B14: W5 | C14: Skills | D14: Monday | E14: Tell about a skill you had to build from scratch. | F14: Describe the skill, why you needed it, how you learned it, and the measurable result. Use STAR Method. | G14: Structure a clear story with specific actions, resources used, challenges overcome, and outcomes using the STAR method. | H14: Can use STAR Method clearly.
B15: WEEK 6 - SELF-AWARENESS |
B16: W6 | C16: Self-awareness | D16: Monday | E16: How do you react to criticism? | F16: Explain how you listen, reflect, act on the feedback, and share a real example of improvement. | G16: Present criticism positively, avoid defensiveness, and use the STAR method to highlight growth and improvement. | H16: Demonstrate coachability, emotional maturity, and a willingness to learn from feedback.
B17: WEEK 7 - SELF-AWARENESS |
B18: W7 | C18: Self-awareness | D18: Monday | E18: What motivates you? | F18: Share what genuinely drives you, explain why it matters, and support it with a relevant example. | G18: Connect personal motivation to job performance and reinforce it with a specific, authentic example. | H18: Demonstrate self-awareness, intrinsic motivation.
B19: WEEK 8 - Career Goals |
B20: W8 | C20: Career Goals | D20: Monday | E20: What are your short-term and long-term goals? | F20: State your short-term and long-term goals, explain how they are connected, and align them with the role. | G20: Present realistic, role-aligned goals that show progression and long-term value to the organization. | H20: Demonstrate career clarity, ambition, and commitment to continuous growth.
B21: WEEK 9 - BEHAVIORAL |
B22: W9 | C22: Behavioral | D22: Monday | E22: Tell about a time you worked in a team. | F22: Describe the team situation, your specific role, how you collaborated, and the outcome. Use STAR Method. | G22: Emphasize their individual contribution, conflict resolution (if any), and the positive impact using the STAR method. | H22: Demonstrate teamwork, communication, collaboration, and contribution toward a common goal.
B23: WEEK 10 - STRENGTHS |
B24: W10 | C24: Situational | D24: Monday | E24: How would you handle work pressure? | F24: Explain how you prioritize tasks, stay calm under pressure, and share a real example of handling a demanding situation. | G24: Emphasize a structured approach, positive mindset, and measurable results using the STAR method. | H24: Demonstrate resilience, time management, problem-solving, and the ability to perform under pressure.

Sheet Mr Sandeep Kumar
A1: S.No | B1: Roll No | C1: Email-ID | D1: Student Name | E1: Mobile No | F1: Group | G1: Week 1 | H1: Week 2 | I1: Week 3 | J1: Week 4 | K1: Week 5 | L1: Week 6 | M1: Week 7 | N1: Week 8 | O1: Week 9 | P1: Week 10
G2: Mon | H2: Mon | I2: Mon | J2: Mon | K2: Mon | L2: Mon | M2: Mon | N2: Mon | O2: Mon | P2: Mon
A3: 1 | B3: 26PGDM001 | C3: 28-Aadya.Shreysee@fiib.edu.in | D3: Aadya Shreysee | F3: group 1 | Q3: =COUNTA(G3:P3) -> 0
A4: 2 | B4: 26PGDM002 | C4: 28-aditi.lakhotia@fiib.edu.in | D4: Aditi Lakhotia | Q4: =COUNTA(G4:P4) -> 0
A5: 3 | B5: 26PGDM003 | C5: 28-Amisha.Kumari@fiib.edu.in | D5: Amisha Kumari | E5: 90059 94838 | Q5: =COUNTA(G5:P5) -> 0
A6: 4 | B6: 26PGDM004 | C6: 28-Anandita.Parihar@fiib.edu.in | D6: Anandita Parihar | Q6: =COUNTA(G6:P6) -> 0
A7: 5 | B7: 26PGDM005 | C7: 28-aniket.sinha@fiib.edu.in | D7: Aniket Sinha | Q7: =COUNTA(G7:P7) -> 0
A8: 6 | B8: 26PGDM006 | C8: 28-Anjali.Tiwari@fiib.edu.in | D8: Anjali Tiwari | Q8: =COUNTA(G8:P8) -> 0
A9: 7 | B9: 26PGDM007 | C9: 28-Anushka.Singh@fiib.edu.in | D9: Anushka Singh | Q9: =COUNTA(G9:P9) -> 0
A10: 8 | B10: 26PGDM008 | C10: 28-Anushka.Tiwari@fiib.edu.in | D10: Anushka Tiwari | Q10: =COUNTA(G10:P10) -> 0
A11: 9 | B11: 26PGDM009 | C11: 28-arshalan.noor@fiib.edu.in | D11: Arshalan Noor | Q11: =COUNTA(G11:P11) -> 0
A12: 10 | B12: 26PGDM010 | C12: 28-Chandan.Pant@fiib.edu.in | D12: Chandan Pant | Q12: =COUNTA(G12:P12) -> 0
A14: 1 | B14: 26PGDM011 | C14: 28-Dherya.Mittal@fiib.edu.in | D14: Dherya Mittal | F14: Group 2 | Q14: =COUNTA(G14:P14) -> 0
A15: 2 | B15: 26PGDM012 | C15: 28-Ekta.Singh@fiib.edu.in | D15: Ekta Singh | Q15: =COUNTA(G15:P15) -> 0
A16: 3 | B16: 26PGDM013 | C16: 28-Farheen.Khan@fiib.edu.in | D16: Farheen Khan | E16: 93999 95750 | Q16: =COUNTA(G16:P16) -> 0
A17: 4 | B17: 26PGDM014 | C17: 28-Jaideep.Kalra@fiib.edu.in | D17: Jaideep Singh Kalra | Q17: =COUNTA(G17:P17) -> 0
A18: 5 | B18: 26PGDM015 | C18: 28-Joy.Mann@fiib.edu.in | D18: Joy Mann | Q18: =COUNTA(G18:P18) -> 0
A19: 6 | B19: 26PGDM016 | C19: 28-Khushi.Gupta@fiib.edu.in | D19: Khushi Gupta | Q19: =COUNTA(G19:P19) -> 0
A20: 7 | B20: 26PGDM017 | C20: 28-Khushi.Kumari@fiib.edu.in | D20: Khushi Kumari | Q20: =COUNTA(G20:P20) -> 0
A21: 8 | B21: 26PGDM018 | C21: 28-laiba.arzoo@fiib.edu.in | D21: Laiba Arzoo | E21: 99718 69252 | Q21: =COUNTA(G21:P21) -> 0
A22: 9 | B22: 26PGDM019 | C22: 28-lakshya.antil@fiib.edu.in | D22: Lakshya Antil | Q22: =COUNTA(G22:P22) -> 0
A23: 10 | B23: 26PGDM020 | C23: 28-lakshya.seth@fiib.edu.in | D23: Lakshya Seth | Q23: =COUNTA(G23:P23) -> 0
Q24: =COUNTA(G24:P24) -> 0
A25: 1 | B25: 26PGDM021 | C25: 28-Leena.Tamulcar@fiib.edu.in | D25: Leena Tamulcar | F25: Group 3 | Q25: =COUNTA(G25:P25) -> 0
A26: 2 | B26: 26PGDM022 | C26: 28-Madhav.Arora@fiib.edu.in | D26: Madhav Arora | Q26: =COUNTA(G26:P26) -> 0
A27: 3 | B27: 26PGDM023 | C27: 28-Manuj.Dhiman@fiib.edu.in | D27: Manuj Dhiman | Q27: =COUNTA(G27:P27) -> 0
A28: 4 | B28: 26PGDM024 | C28: 28-Manvi.Jain@fiib.edu.in | D28: Manvi Jain | Q28: =COUNTA(G28:P28) -> 0
A29: 5 | B29: 26PGDM025 | C29: 28-Neha.Vishwakarma@fiib.edu.in | D29: Neha Vishwakarma | E29: 99273 93418 | Q29: =COUNTA(G29:P29) -> 0
A30: 6 | B30: 26PGDM026 | C30: 28-Rajat.Dargar@fiib.edu.in | D30: Rajat Dargar | E30: 88265 76069 | Q30: =COUNTA(G30:P30) -> 0
A31: 7 | B31: 26PGDM027 | C31: 28-Rudransh.Tewari@fiib.edu.in | D31: Rudransh Tewari | E31: 95280 73195 | Q31: =COUNTA(G31:P31) -> 0
A32: 8 | B32: 26PGDM028 | C32: 28-Samir.Wadhawan@fiib.edu.in | D32: Samir Wadhawan | Q32: =COUNTA(G32:P32) -> 0
A33: 9 | B33: 26PGDM029 | C33: 28-Shriya.Srivastava@fiib.edu.in | D33: Shriya Srivastava | E33: 93051 28823 | Q33: =COUNTA(G33:P33) -> 0
A34: 10 | B34: 26PGDM030 | C34: 28-Somaina.Narzary@fiib.edu.in | D34: Somaina Narzary | Q34: =COUNTA(G34:P34) -> 0
A36: 1 | B36: 26PGDM031 | C36: 28-sunny.kumar@fiib.edu.in | D36: Sunny Kumar | F36: Group 4 | Q36: =COUNTA(G36:P36) -> 0
A37: 2 | B37: 26PGDM032 | C37: 28-Swetank.Singh@fiib.edu.in | D37: Swetank Singh | Q37: =COUNTA(G37:P37) -> 0
A38: 3 | B38: 26PGDM033 | C38: 28-Tanya.Chauhan@fiib.edu.in | D38: Tanya Chauhan | Q38: =COUNTA(G38:P38) -> 0
A39: 4 | B39: 26PGDM034 | C39: 28-Utkarsh.Singh@fiib.edu.in | D39: Utkarsh Singh | Q39: =COUNTA(G39:P39) -> 0
A40: 5 | B40: 26PGDM035 | C40: 28-Vaidehi.Singh@fiib.edu.in | D40: Vaidehi Singh | Q40: =COUNTA(G40:P40) -> 0
A41: 6 | B41: 26PGDM036 | C41: 28-Vatsal.Nair@fiib.edu.in | D41: Vatsal Nair | Q41: =COUNTA(G41:P41) -> 0
A42: 7 | B42: 26PGDM061 | C42: 28-Abhinav.Sharma@fiib.edu.in | D42: Abhinav Sharma | Q42: =COUNTA(G42:P42) -> 0
...

Sheet Student Tracker
A1: ZIP AHEAD - Student Performance Tracker
A2: A Structured Response Development System for PGDM Students
A3: Score each session out of 10 | Grades auto-calculate | Status auto-updates
A5: S.No | B5: Roll No | C5: Email Student Name | D5: Student Name | E5: Mobile | F5: Domain | G5: Week 1 | H5: Week 2 | I5: Week 3 | J5: Week 4 | K5: Week 5 | L5: Week 6 | M5: Week 7 | N5: Week 8 | O5: Week 9 | P5: Week 10 | Q5: Total (/100) | R5: Avg (/10) | S5: Grade | T5: Status
G6: Mon | H6: Mon | I6: Mon | J6: Mon | K6: Mon | L6: Mon | M6: Mon
A7: 1 | B7: 26PGDM001 | C7: 28-Aadya.Shreysee@fiib.edu.in | D7: Aadya Shreysee | G7: {=IFERROR(INDEX('Mr Sandeep Kumar'!G:G,MATCH($B7,'Mr Sandeep Kumar'!$B:$B,0)),IFERROR(INDEX('Mr Manu Vikraman'!G:G,MATCH($B7,'Mr Manu Vikraman'!$B:$B,0)),""))} | H7: {=IFERROR(INDEX('Mr Sandeep Kumar'!H:H,MATCH($B7,'Mr Sandeep Kumar'!$B:$B,0)),IFERROR(INDEX('Mr Manu Vikraman'!H:H,MATCH($B7,'Mr Manu Vikraman'!$B:$B,0)),""))} | I7: {=IFERROR(INDEX('Mr Sandeep Kumar'!I:I,MATCH($B7,'Mr Sandeep Kumar'!$B:$B,0)),IFERROR(INDEX('Mr Manu Vikraman'!I:I,MATCH($B7,'Mr Manu Vikraman'!$B:$B,0)),""))} | J7: {=IFERROR(INDEX('Mr Sandeep Kumar'!J:J,MATCH($B7,'Mr Sandeep Kumar'!$B:$B,0)),IFERROR(INDEX('Mr Manu Vikraman'!J:J,MATCH($B7,'Mr Manu Vikraman'!$B:$B,0)),""))} | K7: {=IFERROR(INDEX('Mr Sandeep Kumar'!K:K,MATCH($B7,'Mr Sandeep Kumar'!$B:$B,0)),IFERROR(INDEX('Mr Manu Vikraman'!K:K,MATCH($B7,'Mr Manu Vikraman'!$B:$B,0)),""))} | L7: {=IFERROR(INDEX('Mr Sandeep Kumar'!L:L,MATCH($B7,'Mr Sandeep Kumar'!$B:$B,0)),IFERROR(INDEX('Mr Manu Vikraman'!L:L,MATCH($B7,'Mr Manu Vikraman'!$B:$B,0)),""))} | M7: {=IFERROR(INDEX('Mr Sandeep Kumar'!M:M,MATCH($B7,'Mr Sandeep Kumar'!$B:$B,0)),IFERROR(INDEX('Mr Manu Vikraman'!M:M,MATCH($B7,'Mr Manu Vikraman'!$B:$B,0)),""))} | N7: {=IFERROR(INDEX('Mr Sandeep Kumar'!N:N,MATCH($B7,'Mr Sandeep Kumar'!$B:$B,0)),IFERROR(INDEX('Mr Manu Vikraman'!N:N,MATCH($B7,'Mr Manu Vikraman'!$B:$B,0)),""))} | O7: {=IFERROR(INDEX('Mr Sandeep Kumar'!O:O,MATCH($B7,'Mr Sandeep Kumar'!$B:$B,0)),IFERROR(INDEX('Mr Manu Vikraman'!O:O,MATCH($B7,'Mr Manu Vikraman'!$B:$B,0)),""))} | P7: {=IFERROR(INDEX('Mr Sandeep Kumar'!P:P,MATCH($B7,'Mr Sandeep Kumar'!$B:$B,0)),IFERROR(INDEX('Mr Manu Vikraman'!P:P,MATCH($B7,'Mr Manu Vikraman'!$B:$B,0)),""))} | Q7: =IFERROR(SUM(G7:P7),0) -> 0 | R7: =IFERROR(Q7/IF(COUNTIF(G7:P7,">0")=0,1,COUNTIF(G7:P7,">0")),0) -> 0 | S7: =IF(R7>=9,"A+",IF(R7>=8,"A",IF(R7>=7,"B+",IF(R7>=6,"B",IF(R7>=5,"C","D"))))) -> D | T7: =IF(COUNTIF(G7:P7,">0")=10,"Completed",IF(COUNTIF(G7:P7,">0")>=5,"In Progress",IF(COUNTIF(G7:P7,">0")>0,"Started","Not Started"))) -> Not Started
A8: 2 | B8: 26PGDM002 | C8: 28-aditi.lakhotia@fiib.edu.in | D8: Aditi Lakhotia | G8: {=IFERROR(INDEX('Mr Sandeep Kumar'!G:G,MATCH($B8,'Mr Sandeep Kumar'!$B:$B,0)),IFERROR(INDEX('Mr Manu Vikraman'!G:G,MATCH($B8,'Mr Manu Vikraman'!$B:$B,0)),""))} | H8: {=IFERROR(INDEX('Mr Sandeep Kumar'!H:H,MATCH($B8,'Mr Sandeep Kumar'!$B:$B,0)),IFERROR(INDEX('Mr Manu Vikraman'!H:H,MATCH($B8,'Mr Manu Vikraman'!$B:$B,0)),""))} | I8: {=IFERROR(INDEX('Mr Sandeep Kumar'!I:I,MATCH($B8,'Mr Sandeep Kumar'!$B:$B,0)),IFERROR(INDEX('Mr Manu Vikraman'!I:I,MATCH($B8,'Mr Manu Vikraman'!$B:$B,0)),""))} | J8: {=IFERROR(INDEX('Mr Sandeep Kumar'!J:J,MATCH($B8,'Mr Sandeep Kumar'!$B:$B,0)),IFERROR(INDEX('Mr Manu Vikraman'!J:J,MATCH($B8,'Mr Manu Vikraman'!$B:$B,0)),""))} | K8: {=IFERROR(INDEX('Mr Sandeep Kumar'!K:K,MATCH($B8,'Mr Sandeep Kumar'!$B:$B,0)),IFERROR(INDEX('Mr Manu Vikraman'!K:K,MATCH($B8,'Mr Manu Vikraman'!$B:$B,0)),""))} | L8: {=IFERROR(INDEX('Mr Sandeep Kumar'!L:L,MATCH($B8,'Mr Sandeep Kumar'!$B:$B,0)),IFERROR(INDEX('Mr Manu Vikraman'!L:L,MATCH($B8,'Mr Manu Vikraman'!$B:$B,0)),""))} | M8: {=IFERROR(INDEX('Mr Sandeep Kumar'!M:M,MATCH($B8,'Mr Sandeep Kumar'!$B:$B,0)),IFERROR(INDEX('Mr Manu Vikraman'!M:M,MATCH($B8,'Mr Manu Vikraman'!$B:$B,0)),""))} | N8: {=IFERROR(INDEX('Mr Sandeep Kumar'!N:N,MATCH($B8,'Mr Sandeep Kumar'!$B:$B,0)),IFERROR(INDEX('Mr Manu Vikraman'!N:N,MATCH($B8,'Mr Manu Vikraman'!$B:$B,0)),""))} | O8: {=IFERROR(INDEX('Mr Sandeep Kumar'!O:O,MATCH($B8,'Mr Sandeep Kumar'!$B:$B,0)),IFERROR(INDEX('Mr Manu Vikraman'!O:O,MATCH($B8,'Mr Manu Vikraman'!$B:$B,0)),""))} | P8: {=IFERROR(INDEX('Mr Sandeep Kumar'!P:P,MATCH($B8,'Mr Sandeep Kumar'!$B:$B,0)),IFERROR(INDEX('Mr Manu Vikraman'!P:P,MATCH($B8,'Mr Manu Vikraman'!$B:$B,0)),""))} | Q8: =IFERROR(SUM(G8:P8),0) -> 0 | R8: =IFERROR(Q8/IF(COUNTIF(G8:P8,">0")=0,1,COUNTIF(G8:P8,">0")),0) -> 0 | S8: =IF(R8>=9,"A+",IF(R8>=8,"A",IF(R8>=7,"B+",IF(R8>=6,"B",IF(R8>=5,"C","D"))))) -> D | T8: =IF(COUNTIF(G8:P8,">0")=10,"Completed",IF(COUNTIF(G8:P8,">0")>=5,"In Progress",IF(COUNTIF(G8:P8,">0")>0,"Started","Not Started"))) -> Not Started
A9: 3 | B9: 26PGDM003 | C9: 28-Amisha.Kumari@fiib.edu.in | D9: Amisha Kumari | G9: {=IFERROR(INDEX('Mr Sandeep Kumar'!G:G,MATCH($B9,'Mr Sandeep Kumar'!$B:$B,0)),IFERROR(INDEX('Mr Manu Vikraman'!G:G,MATCH($B9,'Mr Manu Vikraman'!$B:$B,0)),""))} | H9: {=IFERROR(INDEX('Mr Sandeep Kumar'!H:H,MATCH($B9,'Mr Sandeep Kumar'!$B:$B,0)),IFERROR(INDEX('Mr Manu Vikraman'!H:H,MATCH($B9,'Mr Manu Vikraman'!$B:$B,0)),""))} | I9: {=IFERROR(INDEX('Mr Sandeep Kumar'!I:I,MATCH($B9,'Mr Sandeep Kumar'!$B:$B,0)),IFERROR(INDEX('Mr Manu Vikraman'!I:I,MATCH($B9,'Mr Manu Vikraman'!$B:$B,0)),""))} | J9: {=IFERROR(INDEX('Mr Sandeep Kumar'!J:J,MATCH($B9,'Mr Sandeep Kumar'!$B:$B,0)),IFERROR(INDEX('Mr Manu Vikraman'!J:J,MATCH($B9,'Mr Manu Vikraman'!$B:$B,0)),""))} | K9: {=IFERROR(INDEX('Mr Sandeep Kumar'!K:K,MATCH($B9,'Mr Sandeep Kumar'!$B:$B,0)),IFERROR(INDEX('Mr Manu Vikraman'!K:K,MATCH($B9,'Mr Manu Vikraman'!$B:$B,0)),""))} | L9: {=IFERROR(INDEX('Mr Sandeep Kumar'!L:L,MATCH($B9,'Mr Sandeep Kumar'!$B:$B,0)),IFERROR(INDEX('Mr Manu Vikraman'!L:L,MATCH($B9,'Mr Manu Vikraman'!$B:$B,0)),""))} | M9: {=IFERROR(INDEX('Mr Sandeep Kumar'!M:M,MATCH($B9,'Mr Sandeep Kumar'!$B:$B,0)),IFERROR(INDEX('Mr Manu Vikraman'!M:M,MATCH($B9,'Mr Manu Vikraman'!$B:$B,0)),""))} | N9: {=IFERROR(INDEX('Mr Sandeep Kumar'!N:N,MATCH($B9,'Mr Sandeep Kumar'!$B:$B,0)),IFERROR(INDEX('Mr Manu Vikraman'!N:N,MATCH($B9,'Mr Manu Vikraman'!$B:$B,0)),""))} | O9: {=IFERROR(INDEX('Mr Sandeep Kumar'!O:O,MATCH($B9,'Mr Sandeep Kumar'!$B:$B,0)),IFERROR(INDEX('Mr Manu Vikraman'!O:O,MATCH($B9,'Mr Manu Vikraman'!$B:$B,0)),""))} | P9: {=IFERROR(INDEX('Mr Sandeep Kumar'!P:P,MATCH($B9,'Mr Sandeep Kumar'!$B:$B,0)),IFERROR(INDEX('Mr Manu Vikraman'!P:P,MATCH($B9,'Mr Manu Vikraman'!$B:$B,0)),""))} | Q9: =IFERROR(SUM(G9:P9),0) -> 0 | R9: =IFERROR(Q9/IF(COUNTIF(G9:P9,">0")=0,1,COUNTIF(G9:P9,">0")),0) -> 0 | S9: =IF(R9>=9,"A+",IF(R9>=8,"A",IF(R9>=7,"B+",IF(R9>=6,"B",IF(R9>=5,"C","D"))))) -> D | T9: =IF(COUNTIF(G9:P9,">0")=10,"Completed",IF(COUNTIF(G9:P9,">0")>=5,"In Progress",IF(COUNTIF(G9:P9,">0")>0,"Started","Not Started"))) -> Not Started
A10: 4 | B10: 26PGDM004 | C10: 28-Anandita.Parihar@fiib.edu.in | D10: Anandita Parihar | G10: {=IFERROR(INDEX('Mr Sandeep Kumar'!G:G,MATCH($B10,'Mr Sandeep Kumar'!$B:$B,0)),IFERROR(INDEX('Mr Manu Vikraman'!G:G,MATCH($B10,'Mr Manu Vikraman'!$B:$B,0)),""))} | H10: {=IFERROR(INDEX('Mr Sandeep Kumar'!H:H,MATCH($B10,'Mr Sandeep Kumar'!$B:$B,0)),IFERROR(INDEX('Mr Manu Vikraman'!H:H,MATCH($B10,'Mr Manu Vikraman'!$B:$B,0)),""))} | I10: {=IFERROR(INDEX('Mr Sandeep Kumar'!I:I,MATCH($B10,'Mr Sandeep Kumar'!$B:$B,0)),IFERROR(INDEX('Mr Manu Vikraman'!I:I,MATCH($B10,'Mr Manu Vikraman'!$B:$B,0)),""))} | J10: {=IFERROR(INDEX('Mr Sandeep Kumar'!J:J,MATCH($B10,'Mr Sandeep Kumar'!$B:$B,0)),IFERROR(INDEX('Mr Manu Vikraman'!J:J,MATCH($B10,'Mr Manu Vikraman'!$B:$B,0)),""))} | K10: {=IFERROR(INDEX('Mr Sandeep Kumar'!K:K,MATCH($B10,'Mr Sandeep Kumar'!$B:$B,0)),IFERROR(INDEX('Mr Manu Vikraman'!K:K,MATCH($B10,'Mr Manu Vikraman'!$B:$B,0)),""))} | L10: {=IFERROR(INDEX('Mr Sandeep Kumar'!L:L,MATCH($B10,'Mr Sandeep Kumar'!$B:$B,0)),IFERROR(INDEX('Mr Manu Vikraman'!L:L,MATCH($B10,'Mr Manu Vikraman'!$B:$B,0)),""))} | M10: {=IFERROR(INDEX('Mr Sandeep Kumar'!M:M,MATCH($B10,'Mr Sandeep Kumar'!$B:$B,0)),IFERROR(INDEX('Mr Manu Vikraman'!M:M,MATCH($B10,'Mr Manu Vikraman'!$B:$B,0)),""))} | N10: {=IFERROR(INDEX('Mr Sandeep Kumar'!N:N,MATCH($B10,'Mr Sandeep Kumar'!$B:$B,0)),IFERROR(INDEX('Mr Manu Vikraman'!N:N,MATCH($B10,'Mr Manu Vikraman'!$B:$B,0)),""))} | O10: {=IFERROR(INDEX('Mr Sandeep Kumar'!O:O,MATCH($B10,'Mr Sandeep Kumar'!$B:$B,0)),IFERROR(INDEX('Mr Manu Vikraman'!O:O,MATCH($B10,'Mr Manu Vikraman'!$B:$B,0)),""))} | P10: {=IFERROR(INDEX('Mr Sandeep Kumar'!P:P,MATCH($B10,'Mr Sandeep Kumar'!$B:$B,0)),IFERROR(INDEX('Mr Manu Vikraman'!P:P,MATCH($B10,'Mr Manu Vikraman'!$B:$B,0)),""))} | Q10: =IFERROR(SUM(G10:P10),0) -> 0 | R10: =IFERROR(Q10/IF(COUNTIF(G10:P10,">0")=0,1,COUNTIF(G10:P10,">0")),0) -> 0 | S10: =IF(R10>=9,"A+",IF(R10>=8,"A",IF(R10>=7,"B+",IF(R10>=6,"B",IF(R10>=5,"C","D"))))) -> D | T10: =IF(COUNTIF(G10:P10,">0")=10,"Completed",IF(COUNTIF(G10:P10,">0")>=5,"In Progress",IF(COUNTIF(G10:P10,">0")>0,"Started","Not Started"))) -> Not Started
A11: 5 | B11: 26PGDM005 | C11: 28-aniket.sinha@fiib.edu.in | D11: Aniket Sinha | G11: {=IFERROR(INDEX('Mr Sandeep Kumar'!G:G,MATCH($B11,'Mr Sandeep Kumar'!$B:$B,0)),IFERROR(INDEX('Mr Manu Vikraman'!G:G,MATCH($B11,'Mr Manu Vikraman'!$B:$B,0)),""))} | H11: {=IFERROR(INDEX('Mr Sandeep Kumar'!H:H,MATCH($B11,'Mr Sandeep Kumar'!$B:$B,0)),IFERROR(INDEX('Mr Manu Vikraman'!H:H,MATCH($B11,'Mr Manu Vikraman'!$B:$B,0)),""))} | I11: {=IFERROR(INDEX('Mr Sandeep Kumar'!I:I,MATCH($B11,'Mr Sandeep Kumar'!$B:$B,0)),IFERROR(INDEX('Mr Manu Vikraman'!I:I,MATCH($B11,'Mr Manu Vikraman'!$B:$B,0)),""))} | J11: {=IFERROR(INDEX('Mr Sandeep Kumar'!J:J,MATCH($B11,'Mr Sandeep Kumar'!$B:$B,0)),IFERROR(INDEX('Mr Manu Vikraman'!J:J,MATCH($B11,'Mr Manu Vikraman'!$B:$B,0)),""))} | K11: {=IFERROR(INDEX('Mr Sandeep Kumar'!K:K,MATCH($B11,'Mr Sandeep Kumar'!$B:$B,0)),IFERROR(INDEX('Mr Manu Vikraman'!K:K,MATCH($B11,'Mr Manu Vikraman'!$B:$B,0)),""))} | L11: {=IFERROR(INDEX('Mr Sandeep Kumar'!L:L,MATCH($B11,'Mr Sandeep Kumar'!$B:$B,0)),IFERROR(INDEX('Mr Manu Vikraman'!L:L,MATCH($B11,'Mr Manu Vikraman'!$B:$B,0)),""))} | M11: {=IFERROR(INDEX('Mr Sandeep Kumar'!M:M,MATCH($B11,'Mr Sandeep Kumar'!$B:$B,0)),IFERROR(INDEX('Mr Manu Vikraman'!M:M,MATCH($B11,'Mr Manu Vikraman'!$B:$B,0)),""))} | N11: {=IFERROR(INDEX('Mr Sandeep Kumar'!N:N,MATCH($B11,'Mr Sandeep Kumar'!$B:$B,0)),IFERROR(INDEX('Mr Manu Vikraman'!N:N,MATCH($B11,'Mr Manu Vikraman'!$B:$B,0)),""))} | O11: {=IFERROR(INDEX('Mr Sandeep Kumar'!O:O,MATCH($B11,'Mr Sandeep Kumar'!$B:$B,0)),IFERROR(INDEX('Mr Manu Vikraman'!O:O,MATCH($B11,'Mr Manu Vikraman'!$B:$B,0)),""))} | P11: {=IFERROR(INDEX('Mr Sandeep Kumar'!P:P,MATCH($B11,'Mr Sandeep Kumar'!$B:$B,0)),IFERROR(INDEX('Mr Manu Vikraman'!P:P,MATCH($B11,'Mr Manu Vikraman'!$B:$B,0)),""))} | Q11: =IFERROR(SUM(G11:P11),0) -> 0 | R11: =IFERROR(Q11/IF(COUNTIF(G11:P11,">0")=0,1,COUNTIF(G11:P11,">0")),0) -> 0 | S11: =IF(R11>=9,"A+",IF(R11>=8,"A",IF(R11>=7,"B+",IF(R11>=6,"B",IF(R11>=5,"C","D"))))) -> D | T11: =IF(COUNTIF(G11:P11,">0")=10,"Completed",IF(COUNTIF(G11:P11,">0")>=5,"In Progress",IF(COUNTIF(G11:P11,">0")>0,"Started","Not Started"))) -> Not Started
A12: 6 | B12: 26PGDM006 | C12: 28-Anjali.Tiwari@fiib.edu.in | D12: Anjali Tiwari | G12: {=IFERROR(INDEX('Mr Sandeep Kumar'!G:G,MATCH($B12,'Mr Sandeep Kumar'!$B:$B,0)),IFERROR(INDEX('Mr Manu Vikraman'!G:G,MATCH($B12,'Mr Manu Vikraman'!$B:$B,0)),""))} | H12: {=IFERROR(INDEX('Mr Sandeep Kumar'!H:H,MATCH($B12,'Mr Sandeep Kumar'!$B:$B,0)),IFERROR(INDEX('Mr Manu Vikraman'!H:H,MATCH($B12,'Mr Manu Vikraman'!$B:$B,0)),""))} | I12: {=IFERROR(INDEX('Mr Sandeep Kumar'!I:I,MATCH($B12,'Mr Sandeep Kumar'!$B:$B,0)),IFERROR(INDEX('Mr Manu Vikraman'!I:I,MATCH($B12,'Mr Manu Vikraman'!$B:$B,0)),""))} | J12: {=IFERROR(INDEX('Mr Sandeep Kumar'!J:J,MATCH($B12,'Mr Sandeep Kumar'!$B:$B,0)),IFERROR(INDEX('Mr Manu Vikraman'!J:J,MATCH($B12,'Mr Manu Vikraman'!$B:$B,0)),""))} | K12: {=IFERROR(INDEX('Mr Sandeep Kumar'!K:K,MATCH($B12,'Mr Sandeep Kumar'!$B:$B,0)),IFERROR(INDEX('Mr Manu Vikraman'!K:K,MATCH($B12,'Mr Manu Vikraman'!$B:$B,0)),""))} | L12: {=IFERROR(INDEX('Mr Sandeep Kumar'!L:L,MATCH($B12,'Mr Sandeep Kumar'!$B:$B,0)),IFERROR(INDEX('Mr Manu Vikraman'!L:L,MATCH($B12,'Mr Manu Vikraman'!$B:$B,0)),""))} | M12: {=IFERROR(INDEX('Mr Sandeep Kumar'!M:M,MATCH($B12,'Mr Sandeep Kumar'!$B:$B,0)),IFERROR(INDEX('Mr Manu Vikraman'!M:M,MATCH($B12,'Mr Manu Vikraman'!$B:$B,0)),""))} | N12: {=IFERROR(INDEX('Mr Sandeep Kumar'!N:N,MATCH($B12,'Mr Sandeep Kumar'!$B:$B,0)),IFERROR(INDEX('Mr Manu Vikraman'!N:N,MATCH($B12,'Mr Manu Vikraman'!$B:$B,0)),""))} | O12: {=IFERROR(INDEX('Mr Sandeep Kumar'!O:O,MATCH($B12,'Mr Sandeep Kumar'!$B:$B,0)),IFERROR(INDEX('Mr Manu Vikraman'!O:O,MATCH($B12,'Mr Manu Vikraman'!$B:$B,0)),""))} | P12: {=IFERROR(INDEX('Mr Sandeep Kumar'!P:P,MATCH($B12,'Mr Sandeep Kumar'!$B:$B,0)),IFERROR(INDEX('Mr Manu Vikraman'!P:P,MATCH($B12,'Mr Manu Vikraman'!$B:$B,0)),""))} | Q12: =IFERROR(SUM(G12:P12),0) -> 0 | R12: =IFERROR(Q12/IF(COUNTIF(G12:P12,">0")=0,1,COUNTIF(G12:P12,">0")),0) -> 0 | S12: =IF(R12>=9,"A+",IF(R12>=8,"A",IF(R12>=7,"B+",IF(R12>=6,"B",IF(R12>=5,"C","D"))))) -> D | T12: =IF(COUNTIF(G12:P12,">0")=10,"Completed",IF(COUNTIF(G12:P12,">0")>=5,"In Progress",IF(COUNTIF(G12:P12,">0")>0,"Started","Not Started"))) -> Not Started
A13: 7 | B13: 26PGDM007 | C13: 28-Anushka.Singh@fiib.edu.in | D13: Anushka Singh | G13: {=IFERROR(INDEX('Mr Sandeep Kumar'!G:G,MATCH($B13,'Mr Sandeep Kumar'!$B:$B,0)),IFERROR(INDEX('Mr Manu Vikraman'!G:G,MATCH($B13,'Mr Manu Vikraman'!$B:$B,0)),""))} | H13: {=IFERROR(INDEX('Mr Sandeep Kumar'!H:H,MATCH($B13,'Mr Sandeep Kumar'!$B:$B,0)),IFERROR(INDEX('Mr Manu Vikraman'!H:H,MATCH($B13,'Mr Manu Vikraman'!$B:$B,0)),""))} | I13: {=IFERROR(INDEX('Mr Sandeep Kumar'!I:I,MATCH($B13,'Mr Sandeep Kumar'!$B:$B,0)),IFERROR(INDEX('Mr Manu Vikraman'!I:I,MATCH($B13,'Mr Manu Vikraman'!$B:$B,0)),""))} | J13: {=IFERROR(INDEX('Mr Sandeep Kumar'!J:J,MATCH($B13,'Mr Sandeep Kumar'!$B:$B,0)),IFERROR(INDEX('Mr Manu Vikraman'!J:J,MATCH($B13,'Mr Manu Vikraman'!$B:$B,0)),""))} | K13: {=IFERROR(INDEX('Mr Sandeep Kumar'!K:K,MATCH($B13,'Mr Sandeep Kumar'!$B:$B,0)),IFERROR(INDEX('Mr Manu Vikraman'!K:K,MATCH($B13,'Mr Manu Vikraman'!$B:$B,0)),""))} | L13: {=IFERROR(INDEX('Mr Sandeep Kumar'!L:L,MATCH($B13,'Mr Sandeep Kumar'!$B:$B,0)),IFERROR(INDEX('Mr Manu Vikraman'!L:L,MATCH($B13,'Mr Manu Vikraman'!$B:$B,0)),""))} | M13: {=IFERROR(INDEX('Mr Sandeep Kumar'!M:M,MATCH($B13,'Mr Sandeep Kumar'!$B:$B,0)),IFERROR(INDEX('Mr Manu Vikraman'!M:M,MATCH($B13,'Mr Manu Vikraman'!$B:$B,0)),""))} | N13: {=IFERROR(INDEX('Mr Sandeep Kumar'!N:N,MATCH($B13,'Mr Sandeep Kumar'!$B:$B,0)),IFERROR(INDEX('Mr Manu Vikraman'!N:N,MATCH($B13,'Mr Manu Vikraman'!$B:$B,0)),""))} | O13: {=IFERROR(INDEX('Mr Sandeep Kumar'!O:O,MATCH($B13,'Mr Sandeep Kumar'!$B:$B,0)),IFERROR(INDEX('Mr Manu Vikraman'!O:O,MATCH($B13,'Mr Manu Vikraman'!$B:$B,0)),""))} | P13: {=IFERROR(INDEX('Mr Sandeep Kumar'!P:P,MATCH($B13,'Mr Sandeep Kumar'!$B:$B,0)),IFERROR(INDEX('Mr Manu Vikraman'!P:P,MATCH($B13,'Mr Manu Vikraman'!$B:$B,0)),""))} | Q13: =IFERROR(SUM(G13:P13),0) -> 0 | R13: =IFERROR(Q13/IF(COUNTIF(G13:P13,">0")=0,1,COUNTIF(G13:P13,">0")),0) -> 0 | S13: =IF(R13>=9,"A+",IF(R13>=8,"A",IF(R13>=7,"B+",IF(R13>=6,"B",IF(R13>=5,"C","D"))))) -> D | T13: =IF(COUNTIF(G13:P13,">0")=10,"Completed",IF(COUNTIF(G13:P13,">0")>=5,"In Progress",IF(COUNTIF(G13:P13,">0")>0,"Started","Not Started"))) -> Not Started
A14: 8 | B14: 26PGDM008 | C14: 28-Anushka.Tiwari@fiib.edu.in | D14: Anushka Tiwari | G14: {=IFERROR(INDEX('Mr Sandeep Kumar'!G:G,MATCH($B14,'Mr Sandeep Kumar'!$B:$B,0)),IFERROR(INDEX('Mr Manu Vikraman'!G:G,MATCH($B14,'Mr Manu Vikraman'!$B:$B,0)),""))} | H14: {=IFERROR(INDEX('Mr Sandeep Kumar'!H:H,MATCH($B14,'Mr Sandeep Kumar'!$B:$B,0)),IFERROR(INDEX('Mr Manu Vikraman'!H:H,MATCH($B14,'Mr Manu Vikraman'!$B:$B,0)),""))} | I14: {=IFERROR(INDEX('Mr Sandeep Kumar'!I:I,MATCH($B14,'Mr Sandeep Kumar'!$B:$B,0)),IFERROR(INDEX('Mr Manu Vikraman'!I:I,MATCH($B14,'Mr Manu Vikraman'!$B:$B,0)),""))} | J14: {=IFERROR(INDEX('Mr Sandeep Kumar'!J:J,MATCH($B14,'Mr Sandeep Kumar'!$B:$B,0)),IFERROR(INDEX('Mr Manu Vikraman'!J:J,MATCH($B14,'Mr Manu Vikraman'!$B:$B,0)),""))} | K14: {=IFERROR(INDEX('Mr Sandeep Kumar'!K:K,MATCH($B14,'Mr Sandeep Kumar'!$B:$B,0)),IFERROR(INDEX('Mr Manu Vikraman'!K:K,MATCH($B14,'Mr Manu Vikraman'!$B:$B,0)),""))} | L14: {=IFERROR(INDEX('Mr Sandeep Kumar'!L:L,MATCH($B14,'Mr Sandeep Kumar'!$B:$B,0)),IFERROR(INDEX('Mr Manu Vikraman'!L:L,MATCH($B14,'Mr Manu Vikraman'!$B:$B,0)),""))} | M14: {=IFERROR(INDEX('Mr Sandeep Kumar'!M:M,MATCH($B14,'Mr Sandeep Kumar'!$B:$B,0)),IFERROR(INDEX('Mr Manu Vikraman'!M:M,MATCH($B14,'Mr Manu Vikraman'!$B:$B,0)),""))} | N14: {=IFERROR(INDEX('Mr Sandeep Kumar'!N:N,MATCH($B14,'Mr Sandeep Kumar'!$B:$B,0)),IFERROR(INDEX('Mr Manu Vikraman'!N:N,MATCH($B14,'Mr Manu Vikraman'!$B:$B,0)),""))} | O14: {=IFERROR(INDEX('Mr Sandeep Kumar'!O:O,MATCH($B14,'Mr Sandeep Kumar'!$B:$B,0)),IFERROR(INDEX('Mr Manu Vikraman'!O:O,MATCH($B14,'Mr Manu Vikraman'!$B:$B,0)),""))} | P14: {=IFERROR(INDEX('Mr Sandeep Kumar'!P:P,MATCH($B14,'Mr Sandeep Kumar'!$B:$B,0)),IFERROR(INDEX('Mr Manu Vikraman'!P:P,MATCH($B14,'Mr Manu Vikraman'!$B:$B,0)),""))} | Q14: =IFERROR(SUM(G14:P14),0) -> 0 | R14: =IFERROR(Q14/IF(COUNTIF(G14:P14,">0")=0,1,COUNTIF(G14:P14,">0")),0) -> 0 | S14: =IF(R14>=9,"A+",IF(R14>=8,"A",IF(R14>=7,"B+",IF(R14>=6,"B",IF(R14>=5,"C","D"))))) -> D | T14: =IF(COUNTIF(G14:P14,">0")=10,"Completed",IF(COUNTIF(G14:P14,">0")>=5,"In Progress",IF(COUNTIF(G14:P14,">0")>0,"Started","Not Started"))) -> Not Started
A15: 9 | B15: 26PGDM009 | C15: 28-arshalan.noor@fiib.edu.in | D15: Arshalan Noor | G15: {=IFERROR(INDEX('Mr Sandeep Kumar'!G:G,MATCH($B15,'Mr Sandeep Kumar'!$B:$B,0)),IFERROR(INDEX('Mr Manu Vikraman'!G:G,MATCH($B15,'Mr Manu Vikraman'!$B:$B,0)),""))} | H15: {=IFERROR(INDEX('Mr Sandeep Kumar'!H:H,MATCH($B15,'Mr Sandeep Kumar'!$B:$B,0)),IFERROR(INDEX('Mr Manu Vikraman'!H:H,MATCH($B15,'Mr Manu Vikraman'!$B:$B,0)),""))} | I15: {=IFERROR(INDEX('Mr Sandeep Kumar'!I:I,MATCH($B15,'Mr Sandeep Kumar'!$B:$B,0)),IFERROR(INDEX('Mr Manu Vikraman'!I:I,MATCH($B15,'Mr Manu Vikraman'!$B:$B,0)),""))} | J15: {=IFERROR(INDEX('Mr Sandeep Kumar'!J:J,MATCH($B15,'Mr Sandeep Kumar'!$B:$B,0)),IFERROR(INDEX('Mr Manu Vikraman'!J:J,MATCH($B15,'Mr Manu Vikraman'!$B:$B,0)),""))} | K15: {=IFERROR(INDEX('Mr Sandeep Kumar'!K:K,MATCH($B15,'Mr Sandeep Kumar'!$B:$B,0)),IFERROR(INDEX('Mr Manu Vikraman'!K:K,MATCH($B15,'Mr Manu Vikraman'!$B:$B,0)),""))} | L15: {=IFERROR(INDEX('Mr Sandeep Kumar'!L:L,MATCH($B15,'Mr Sandeep Kumar'!$B:$B,0)),IFERROR(INDEX('Mr Manu Vikraman'!L:L,MATCH($B15,'Mr Manu Vikraman'!$B:$B,0)),""))} | M15: {=IFERROR(INDEX('Mr Sandeep Kumar'!M:M,MATCH($B15,'Mr Sandeep Kumar'!$B:$B,0)),IFERROR(INDEX('Mr Manu Vikraman'!M:M,MATCH($B15,'Mr Manu Vikraman'!$B:$B,0)),""))} | N15: {=IFERROR(INDEX('Mr Sandeep Kumar'!N:N,MATCH($B15,'Mr Sandeep Kumar'!$B:$B,0)),IFERROR(INDEX('Mr Manu Vikraman'!N:N,MATCH($B15,'Mr Manu Vikraman'!$B:$B,0)),""))} | O15: {=IFERROR(INDEX('Mr Sandeep Kumar'!O:O,MATCH($B15,'Mr Sandeep Kumar'!$B:$B,0)),IFERROR(INDEX('Mr Manu Vikraman'!O:O,MATCH($B15,'Mr Manu Vikraman'!$B:$B,0)),""))} | P15: {=IFERROR(INDEX('Mr Sandeep Kumar'!P:P,MATCH($B15,'Mr Sandeep Kumar'!$B:$B,0)),IFERROR(INDEX('Mr Manu Vikraman'!P:P,MATCH($B15,'Mr Manu Vikraman'!$B:$B,0)),""))} | Q15: =IFERROR(SUM(G15:P15),0) -> 0 | R15: =IFERROR(Q15/IF(COUNTIF(G15:P15,">0")=0,1,COUNTIF(G15:P15,">0")),0) -> 0 | S15: =IF(R15>=9,"A+",IF(R15>=8,"A",IF(R15>=7,"B+",IF(R15>=6,"B",IF(R15>=5,"C","D"))))) -> D | T15: =IF(COUNTIF(G15:P15,">0")=10,"Completed",IF(COUNTIF(G15:P15,">0")>=5,"In Progress",IF(COUNTIF(G15:P15,">0")>0,"Started","Not Started"))) -> Not Started
A16: 10 | B16: 26PGDM010 | C16: 28-Chandan.Pant@fiib.edu.in | D16: Chandan Pant | G16: {=IFERROR(INDEX('Mr Sandeep Kumar'!G:G,MATCH($B16,'Mr Sandeep Kumar'!$B:$B,0)),IFERROR(INDEX('Mr Manu Vikraman'!G:G,MATCH($B16,'Mr Manu Vikraman'!$B:$B,0)),""))} | H16: {=IFERROR(INDEX('Mr Sandeep Kumar'!H:H,MATCH($B16,'Mr Sandeep Kumar'!$B:$B,0)),IFERROR(INDEX('Mr Manu Vikraman'!H:H,MATCH($B16,'Mr Manu Vikraman'!$B:$B,0)),""))} | I16: {=IFERROR(INDEX('Mr Sandeep Kumar'!I:I,MATCH($B16,'Mr Sandeep Kumar'!$B:$B,0)),IFERROR(INDEX('Mr Manu Vikraman'!I:I,MATCH($B16,'Mr Manu Vikraman'!$B:$B,0)),""))} | J16: {=IFERROR(INDEX('Mr Sandeep Kumar'!J:J,MATCH($B16,'Mr Sandeep Kumar'!$B:$B,0)),IFERROR(INDEX('Mr Manu Vikraman'!J:J,MATCH($B16,'Mr Manu Vikraman'!$B:$B,0)),""))} | K16: {=IFERROR(INDEX('Mr Sandeep Kumar'!K:K,MATCH($B16,'Mr Sandeep Kumar'!$B:$B,0)),IFERROR(INDEX('Mr Manu Vikraman'!K:K,MATCH($B16,'Mr Manu Vikraman'!$B:$B,0)),""))} | L16: {=IFERROR(INDEX('Mr Sandeep Kumar'!L:L,MATCH($B16,'Mr Sandeep Kumar'!$B:$B,0)),IFERROR(INDEX('Mr Manu Vikraman'!L:L,MATCH($B16,'Mr Manu Vikraman'!$B:$B,0)),""))} | M16: {=IFERROR(INDEX('Mr Sandeep Kumar'!M:M,MATCH($B16,'Mr Sandeep Kumar'!$B:$B,0)),IFERROR(INDEX('Mr Manu Vikraman'!M:M,MATCH($B16,'Mr Manu Vikraman'!$B:$B,0)),""))} | N16: {=IFERROR(INDEX('Mr Sandeep Kumar'!N:N,MATCH($B16,'Mr Sandeep Kumar'!$B:$B,0)),IFERROR(INDEX('Mr Manu Vikraman'!N:N,MATCH($B16,'Mr Manu Vikraman'!$B:$B,0)),""))} | O16: {=IFERROR(INDEX('Mr Sandeep Kumar'!O:O,MATCH($B16,'Mr Sandeep Kumar'!$B:$B,0)),IFERROR(INDEX('Mr Manu Vikraman'!O:O,MATCH($B16,'Mr Manu Vikraman'!$B:$B,0)),""))} | P16: {=IFERROR(INDEX('Mr Sandeep Kumar'!P:P,MATCH($B16,'Mr Sandeep Kumar'!$B:$B,0)),IFERROR(INDEX('Mr Manu Vikraman'!P:P,MATCH($B16,'Mr Manu Vikraman'!$B:$B,0)),""))} | Q16: =IFERROR(SUM(G16:P16),0) -> 0 | R16: =IFERROR(Q16/IF(COUNTIF(G16:P16,">0")=0,1,COUNTIF(G16:P16,">0")),0) -> 0 | S16: =IF(R16>=9,"A+",IF(R16>=8,"A",IF(R16>=7,"B+",IF(R16>=6,"B",IF(R16>=5,"C","D"))))) -> D | T16: =IF(COUNTIF(G16:P16,">0")=10,"Completed",IF(COUNTIF(G16:P16,">0")>=5,"In Progress",IF(COUNTIF(G16:P16,">0")>0,"Started","Not Started"))) -> Not Started
A17: 11 | B17: 26PGDM011 | C17: 28-Dherya.Mittal@fiib.edu.in | D17: Dherya Mittal | G17: {=IFERROR(INDEX('Mr Sandeep Kumar'!G:G,MATCH($B17,'Mr Sandeep Kumar'!$B:$B,0)),IFERROR(INDEX('Mr Manu Vikraman'!G:G,MATCH($B17,'Mr Manu Vikraman'!$B:$B,0)),""))} | H17: {=IFERROR(INDEX('Mr Sandeep Kumar'!H:H,MATCH($B17,'Mr Sandeep Kumar'!$B:$B,0)),IFERROR(INDEX('Mr Manu Vikraman'!H:H,MATCH($B17,'Mr Manu Vikraman'!$B:$B,0)),""))} | I17: {=IFERROR(INDEX('Mr Sandeep Kumar'!I:I,MATCH($B17,'Mr Sandeep Kumar'!$B:$B,0)),IFERROR(INDEX('Mr Manu Vikraman'!I:I,MATCH($B17,'Mr Manu Vikraman'!$B:$B,0)),""))} | J17: {=IFERROR(INDEX('Mr Sandeep Kumar'!J:J,MATCH($B17,'Mr Sandeep Kumar'!$B:$B,0)),IFERROR(INDEX('Mr Manu Vikraman'!J:J,MATCH($B17,'Mr Manu Vikraman'!$B:$B,0)),""))} | K17: {=IFERROR(INDEX('Mr Sandeep Kumar'!K:K,MATCH($B17,'Mr Sandeep Kumar'!$B:$B,0)),IFERROR(INDEX('Mr Manu Vikraman'!K:K,MATCH($B17,'Mr Manu Vikraman'!$B:$B,0)),""))} | L17: {=IFERROR(INDEX('Mr Sandeep Kumar'!L:L,MATCH($B17,'Mr Sandeep Kumar'!$B:$B,0)),IFERROR(INDEX('Mr Manu Vikraman'!L:L,MATCH($B17,'Mr Manu Vikraman'!$B:$B,0)),""))} | M17: {=IFERROR(INDEX('Mr Sandeep Kumar'!M:M,MATCH($B17,'Mr Sandeep Kumar'!$B:$B,0)),IFERROR(INDEX('Mr Manu Vikraman'!M:M,MATCH($B17,'Mr Manu Vikraman'!$B:$B,0)),""))} | N17: {=IFERROR(INDEX('Mr Sandeep Kumar'!N:N,MATCH($B17,'Mr Sandeep Kumar'!$B:$B,0)),IFERROR(INDEX('Mr Manu Vikraman'!N:N,MATCH($B17,'Mr Manu Vikraman'!$B:$B,0)),""))} | O17: {=IFERROR(INDEX('Mr Sandeep Kumar'!O:O,MATCH($B17,'Mr Sandeep Kumar'!$B:$B,0)),IFERROR(INDEX('Mr Manu Vikraman'!O:O,MATCH($B17,'Mr Manu Vikraman'!$B:$B,0)),""))} | P17: {=IFERROR(INDEX('Mr Sandeep Kumar'!P:P,MATCH($B17,'Mr Sandeep Kumar'!$B:$B,0)),IFERROR(INDEX('Mr Manu Vikraman'!P:P,MATCH($B17,'Mr Manu Vikraman'!$B:$B,0)),""))} | Q17: =IFERROR(SUM(G17:P17),0) -> 0 | R17: =IFERROR(Q17/IF(COUNTIF(G17:P17,">0")=0,1,COUNTIF(G17:P17,">0")),0) -> 0 | S17: =IF(R17>=9,"A+",IF(R17>=8,"A",IF(R17>=7,"B+",IF(R17>=6,"B",IF(R17>=5,"C","D"))))) -> D | T17: =IF(COUNTIF(G17:P17,">0")=10,"Completed",IF(COUNTIF(G17:P17,">0")>=5,"In Progress",IF(COUNTIF(G17:P17,">0")>0,"Started","Not Started"))) -> Not Started
A18: 12 | B18: 26PGDM012 | C18: 28-Ekta.Singh@fiib.edu.in | D18: Ekta Singh | G18: {=IFERROR(INDEX('Mr Sandeep Kumar'!G:G,MATCH($B18,'Mr Sandeep Kumar'!$B:$B,0)),IFERROR(INDEX('Mr Manu Vikraman'!G:G,MATCH($B18,'Mr Manu Vikraman'!$B:$B,0)),""))} | H18: {=IFERROR(INDEX('Mr Sandeep Kumar'!H:H,MATCH($B18,'Mr Sandeep Kumar'!$B:$B,0)),IFERROR(INDEX('Mr Manu Vikraman'!H:H,MATCH($B18,'Mr Manu Vikraman'!$B:$B,0)),""))} | I18: {=IFERROR(INDEX('Mr Sandeep Kumar'!I:I,MATCH($B18,'Mr Sandeep Kumar'!$B:$B,0)),IFERROR(INDEX('Mr Manu Vikraman'!I:I,MATCH($B18,'Mr Manu Vikraman'!$B:$B,0)),""))} | J18: {=IFERROR(INDEX('Mr Sandeep Kumar'!J:J,MATCH($B18,'Mr Sandeep Kumar'!$B:$B,0)),IFERROR(INDEX('Mr Manu Vikraman'!J:J,MATCH($B18,'Mr Manu Vikraman'!$B:$B,0)),""))} | K18: {=IFERROR(INDEX('Mr Sandeep Kumar'!K:K,MATCH($B18,'Mr Sandeep Kumar'!$B:$B,0)),IFERROR(INDEX('Mr Manu Vikraman'!K:K,MATCH($B18,'Mr Manu Vikraman'!$B:$B,0)),""))} | L18: {=IFERROR(INDEX('Mr Sandeep Kumar'!L:L,MATCH($B18,'Mr Sandeep Kumar'!$B:$B,0)),IFERROR(INDEX('Mr Manu Vikraman'!L:L,MATCH($B18,'Mr Manu Vikraman'!$B:$B,0)),""))} | M18: {=IFERROR(INDEX('Mr Sandeep Kumar'!M:M,MATCH($B18,'Mr Sandeep Kumar'!$B:$B,0)),IFERROR(INDEX('Mr Manu Vikraman'!M:M,MATCH($B18,'Mr Manu Vikraman'!$B:$B,0)),""))} | N18: {=IFERROR(INDEX('Mr Sandeep Kumar'!N:N,MATCH($B18,'Mr Sandeep Kumar'!$B:$B,0)),IFERROR(INDEX('Mr Manu Vikraman'!N:N,MATCH($B18,'Mr Manu Vikraman'!$B:$B,0)),""))} | O18: {=IFERROR(INDEX('Mr Sandeep Kumar'!O:O,MATCH($B18,'Mr Sandeep Kumar'!$B:$B,0)),IFERROR(INDEX('Mr Manu Vikraman'!O:O,MATCH($B18,'Mr Manu Vikraman'!$B:$B,0)),""))} | P18: {=IFERROR(INDEX('Mr Sandeep Kumar'!P:P,MATCH($B18,'Mr Sandeep Kumar'!$B:$B,0)),IFERROR(INDEX('Mr Manu Vikraman'!P:P,MATCH($B18,'Mr Manu Vikraman'!$B:$B,0)),""))} | Q18: =IFERROR(SUM(G18:P18),0) -> 0 | R18: =IFERROR(Q18/IF(COUNTIF(G18:P18,">0")=0,1,COUNTIF(G18:P18,">0")),0) -> 0 | S18: =IF(R18>=9,"A+",IF(R18>=8,"A",IF(R18>=7,"B+",IF(R18>=6,"B",IF(R18>=5,"C","D"))))) -> D | T18: =IF(COUNTIF(G18:P18,">0")=10,"Completed",IF(COUNTIF(G18:P18,">0")>=5,"In Progress",IF(COUNTIF(G18:P18,">0")>0,"Started","Not Started"))) -> Not Started
... A109: 103 | B109: 26PGDM155 | C109: 28-Vaibhav.Chatterjee@fiib.edu.in | D109: Vaibhav Chatterjee | G109: {=IFERROR(INDEX('Mr Sandeep Kumar'!G:G,MATCH($B109,'Mr Sandeep Kumar'!$B:$B,0)),IFERROR(INDEX('Mr Manu Vikraman'!G:G,MATCH($B109,'Mr Manu Vikraman'!$B:$B,0)),""))} | H109: {=IFERROR(INDEX('Mr Sandeep Kumar'!H:H,MATCH($B109,'Mr Sandeep Kumar'!$B:$B,0)),IFERROR(INDEX('Mr Manu Vikraman'!H:H,MATCH($B109,'Mr Manu Vikraman'!$B:$B,0)),""))} | I109: {=IFERROR(INDEX('Mr Sandeep Kumar'!I:I,MATCH($B109,'Mr Sandeep Kumar'!$B:$B,0)),IFERROR(INDEX('Mr Manu Vikraman'!I:I,MATCH($B109,'Mr Manu Vikraman'!$B:$B,0)),""))} | J109: {=IFERROR(INDEX('Mr Sandeep Kumar'!J:J,MATCH($B109,'Mr Sandeep Kumar'!$B:$B,0)),IFERROR(INDEX('Mr Manu Vikraman'!J:J,MATCH($B109,'Mr Manu Vikraman'!$B:$B,0)),""))} | K109: {=IFERROR(INDEX('Mr Sandeep Kumar'!K:K,MATCH($B109,'Mr Sandeep Kumar'!$B:$B,0)),IFERROR(INDEX('Mr Manu Vikraman'!K:K,MATCH($B109,'Mr Manu Vikraman'!$B:$B,0)),""))} | L109: {=IFERROR(INDEX('Mr Sandeep Kumar'!L:L,MATCH($B109,'Mr Sandeep Kumar'!$B:$B,0)),IFERROR(INDEX('Mr Manu Vikraman'!L:L,MATCH($B109,'Mr Manu Vikraman'!$B:$B,0)),""))} | M109: {=IFERROR(INDEX('Mr Sandeep Kumar'!M:M,MATCH($B109,'Mr Sandeep Kumar'!$B:$B,0)),IFERROR(INDEX('Mr Manu Vikraman'!M:M,MATCH($B109,'Mr Manu Vikraman'!$B:$B,0)),""))} | N109: {=IFERROR(INDEX('Mr Sandeep Kumar'!N:N,MATCH($B109,'Mr Sandeep Kumar'!$B:$B,0)),IFERROR(INDEX('Mr Manu Vikraman'!N:N,MATCH($B109,'Mr Manu Vikraman'!$B:$B,0)),""))} | O109: {=IFERROR(INDEX('Mr Sandeep Kumar'!O:O,MATCH($B109,'Mr Sandeep Kumar'!$B:$B,0)),IFERROR(INDEX('Mr Manu Vikraman'!O:O,MATCH($B109,'Mr Manu Vikraman'!$B:$B,0)),""))} | P109: {=IFERROR(INDEX('Mr Sandeep Kumar'!P:P,MATCH($B109,'Mr Sandeep Kumar'!$B:$B,0)),IFERROR(INDEX('Mr Manu Vikraman'!P:P,MATCH($B109,'Mr Manu Vikraman'!$B:$B,0)),""))} | Q109: =IFERROR(SUM(G109:P109),0) -> 0 | R109: =IFERROR(Q109/IF(COUNTIF(G109:P109,">0")=0,1,COUNTIF(G109:P109,">0")),0) -> 0 | S109: =IF(R109>=9,"A+",IF(R109>=8,"A",IF(R109>=7,"B+",IF(R109>=6,"B",IF(R109>=5,"C","D"))))) -> D | T109: =IF(COUNTIF(G109:P109,">0")=10,"Completed",IF(COUNTIF(G109:P109,">0")>=5,"In Progress",IF(COUNTIF(G109:P109,">0")>0,"Started","Not Started"))) -> Not Started
A110: 104 | C110: 28-yash.jindal@fiib.edu.in | D110: Yash Jindal | G110: {=IFERROR(INDEX('Mr Sandeep Kumar'!G:G,MATCH($B110,'Mr Sandeep Kumar'!$B:$B,0)),IFERROR(INDEX('Mr Manu Vikraman'!G:G,MATCH($B110,'Mr Manu Vikraman'!$B:$B,0)),""))} | H110: {=IFERROR(INDEX('Mr Sandeep Kumar'!H:H,MATCH($B110,'Mr Sandeep Kumar'!$B:$B,0)),IFERROR(INDEX('Mr Manu Vikraman'!H:H,MATCH($B110,'Mr Manu Vikraman'!$B:$B,0)),""))} | I110: {=IFERROR(INDEX('Mr Sandeep Kumar'!I:I,MATCH($B110,'Mr Sandeep Kumar'!$B:$B,0)),IFERROR(INDEX('Mr Manu Vikraman'!I:I,MATCH($B110,'Mr Manu Vikraman'!$B:$B,0)),""))} | J110: {=IFERROR(INDEX('Mr Sandeep Kumar'!J:J,MATCH($B110,'Mr Sandeep Kumar'!$B:$B,0)),IFERROR(INDEX('Mr Manu Vikraman'!J:J,MATCH($B110,'Mr Manu Vikraman'!$B:$B,0)),""))} | K110: {=IFERROR(INDEX('Mr Sandeep Kumar'!K:K,MATCH($B110,'Mr Sandeep Kumar'!$B:$B,0)),IFERROR(INDEX('Mr Manu Vikraman'!K:K,MATCH($B110,'Mr Manu Vikraman'!$B:$B,0)),""))} | L110: {=IFERROR(INDEX('Mr Sandeep Kumar'!L:L,MATCH($B110,'Mr Sandeep Kumar'!$B:$B,0)),IFERROR(INDEX('Mr Manu Vikraman'!L:L,MATCH($B110,'Mr Manu Vikraman'!$B:$B,0)),""))} | M110: {=IFERROR(INDEX('Mr Sandeep Kumar'!M:M,MATCH($B110,'Mr Sandeep Kumar'!$B:$B,0)),IFERROR(INDEX('Mr Manu Vikraman'!M:M,MATCH($B110,'Mr Manu Vikraman'!$B:$B,0)),""))} | N110: {=IFERROR(INDEX('Mr Sandeep Kumar'!N:N,MATCH($B110,'Mr Sandeep Kumar'!$B:$B,0)),IFERROR(INDEX('Mr Manu Vikraman'!N:N,MATCH($B110,'Mr Manu Vikraman'!$B:$B,0)),""))} | O110: {=IFERROR(INDEX('Mr Sandeep Kumar'!O:O,MATCH($B110,'Mr Sandeep Kumar'!$B:$B,0)),IFERROR(INDEX('Mr Manu Vikraman'!O:O,MATCH($B110,'Mr Manu Vikraman'!$B:$B,0)),""))} | P110: {=IFERROR(INDEX('Mr Sandeep Kumar'!P:P,MATCH($B110,'Mr Sandeep Kumar'!$B:$B,0)),IFERROR(INDEX('Mr Manu Vikraman'!P:P,MATCH($B110,'Mr Manu Vikraman'!$B:$B,0)),""))} | Q110: =IFERROR(SUM(G110:P110),0) -> 0 | R110: =IFERROR(Q110/IF(COUNTIF(G110:P110,">0")=0,1,COUNTIF(G110:P110,">0")),0) -> 0 | S110: =IF(R110>=9,"A+",IF(R110>=8,"A",IF(R110>=7,"B+",IF(R110>=6,"B",IF(R110>=5,"C","D"))))) -> D | T110: =IF(COUNTIF(G110:P110,">0")=10,"Completed",IF(COUNTIF(G110:P110,">0")>=5,"In Progress",IF(COUNTIF(G110:P110,">0")>0,"Started","Not Started"))) -> Not Started
A111: 105 | B111: 26PGDMFM001 | C111: 28-aaditya@fiib.edu.in | D111: Aaditya . | G111: {=IFERROR(INDEX('Mr Sandeep Kumar'!G:G,MATCH($B111,'Mr Sandeep Kumar'!$B:$B,0)),IFERROR(INDEX('Mr Manu Vikraman'!G:G,MATCH($B111,'Mr Manu Vikraman'!$B:$B,0)),""))} | H111: {=IFERROR(INDEX('Mr Sandeep Kumar'!H:H,MATCH($B111,'Mr Sandeep Kumar'!$B:$B,0)),IFERROR(INDEX('Mr Manu Vikraman'!H:H,MATCH($B111,'Mr Manu Vikraman'!$B:$B,0)),""))} | I111: {=IFERROR(INDEX('Mr Sandeep Kumar'!I:I,MATCH($B111,'Mr Sandeep Kumar'!$B:$B,0)),IFERROR(INDEX('Mr Manu Vikraman'!I:I,MATCH($B111,'Mr Manu Vikraman'!$B:$B,0)),""))} | J111: {=IFERROR(INDEX('Mr Sandeep Kumar'!J:J,MATCH($B111,'Mr Sandeep Kumar'!$B:$B,0)),IFERROR(INDEX('Mr Manu Vikraman'!J:J,MATCH($B111,'Mr Manu Vikraman'!$B:$B,0)),""))} | K111: {=IFERROR(INDEX('Mr Sandeep Kumar'!K:K,MATCH($B111,'Mr Sandeep Kumar'!$B:$B,0)),IFERROR(INDEX('Mr Manu Vikraman'!K:K,MATCH($B111,'Mr Manu Vikraman'!$B:$B,0)),""))} | L111: {=IFERROR(INDEX('Mr Sandeep Kumar'!L:L,MATCH($B111,'Mr Sandeep Kumar'!$B:$B,0)),IFERROR(INDEX('Mr Manu Vikraman'!L:L,MATCH($B111,'Mr Manu Vikraman'!$B:$B,0)),""))} | M111: {=IFERROR(INDEX('Mr Sandeep Kumar'!M:M,MATCH($B111,'Mr Sandeep Kumar'!$B:$B,0)),IFERROR(INDEX('Mr Manu Vikraman'!M:M,MATCH($B111,'Mr Manu Vikraman'!$B:$B,0)),""))} | N111: {=IFERROR(INDEX('Mr Sandeep Kumar'!N:N,MATCH($B111,'Mr Sandeep Kumar'!$B:$B,0)),IFERROR(INDEX('Mr Manu Vikraman'!N:N,MATCH($B111,'Mr Manu Vikraman'!$B:$B,0)),""))} | O111: {=IFERROR(INDEX('Mr Sandeep Kumar'!O:O,MATCH($B111,'Mr Sandeep Kumar'!$B:$B,0)),IFERROR(INDEX('Mr Manu Vikraman'!O:O,MATCH($B111,'Mr Manu Vikraman'!$B:$B,0)),""))} | P111: {=IFERROR(INDEX('Mr Sandeep Kumar'!P:P,MATCH($B111,'Mr Sandeep Kumar'!$B:$B,0)),IFERROR(INDEX('Mr Manu Vikraman'!P:P,MATCH($B111,'Mr Manu Vikraman'!$B:$B,0)),""))} | Q111: =IFERROR(SUM(G111:P111),0) -> 0 | R111: =IFERROR(Q111/IF(COUNTIF(G111:P111,">0")=0,1,COUNTIF(G111:P111,">0")),0) -> 0 | S111: =IF(R111>=9,"A+",IF(R111>=8,"A",IF(R111>=7,"B+",IF(R111>=6,"B",IF(R111>=5,"C","D"))))) -> D | T111: =IF(COUNTIF(G111:P111,">0")=10,"Completed",IF(COUNTIF(G111:P111,">0")>=5,"In Progress",IF(COUNTIF(G111:P111,">0")>0,"Started","Not Started"))) -> Not Started
A112: 106 | B112: 26PGDMFM002 | C112: 28-Aarushi.Verma@fiib.edu.in | D112: Aarushi Verma | G112: {=IFERROR(INDEX('Mr Sandeep Kumar'!G:G,MATCH($B112,'Mr Sandeep Kumar'!$B:$B,0)),IFERROR(INDEX('Mr Manu Vikraman'!G:G,MATCH($B112,'Mr Manu Vikraman'!$B:$B,0)),""))} | H112: {=IFERROR(INDEX('Mr Sandeep Kumar'!H:H,MATCH($B112,'Mr Sandeep Kumar'!$B:$B,0)),IFERROR(INDEX('Mr Manu Vikraman'!H:H,MATCH($B112,'Mr Manu Vikraman'!$B:$B,0)),""))} | I112: {=IFERROR(INDEX('Mr Sandeep Kumar'!I:I,MATCH($B112,'Mr Sandeep Kumar'!$B:$B,0)),IFERROR(INDEX('Mr Manu Vikraman'!I:I,MATCH($B112,'Mr Manu Vikraman'!$B:$B,0)),""))} | J112: {=IFERROR(INDEX('Mr Sandeep Kumar'!J:J,MATCH($B112,'Mr Sandeep Kumar'!$B:$B,0)),IFERROR(INDEX('Mr Manu Vikraman'!J:J,MATCH($B112,'Mr Manu Vikraman'!$B:$B,0)),""))} | K112: {=IFERROR(INDEX('Mr Sandeep Kumar'!K:K,MATCH($B112,'Mr Sandeep Kumar'!$B:$B,0)),IFERROR(INDEX('Mr Manu Vikraman'!K:K,MATCH($B112,'Mr Manu Vikraman'!$B:$B,0)),""))} | L112: {=IFERROR(INDEX('Mr Sandeep Kumar'!L:L,MATCH($B112,'Mr Sandeep Kumar'!$B:$B,0)),IFERROR(INDEX('Mr Manu Vikraman'!L:L,MATCH($B112,'Mr Manu Vikraman'!$B:$B,0)),""))} | M112: {=IFERROR(INDEX('Mr Sandeep Kumar'!M:M,MATCH($B112,'Mr Sandeep Kumar'!$B:$B,0)),IFERROR(INDEX('Mr Manu Vikraman'!M:M,MATCH($B112,'Mr Manu Vikraman'!$B:$B,0)),""))} | N112: {=IFERROR(INDEX('Mr Sandeep Kumar'!N:N,MATCH($B112,'Mr Sandeep Kumar'!$B:$B,0)),IFERROR(INDEX('Mr Manu Vikraman'!N:N,MATCH($B112,'Mr Manu Vikraman'!$B:$B,0)),""))} | O112: {=IFERROR(INDEX('Mr Sandeep Kumar'!O:O,MATCH($B112,'Mr Sandeep Kumar'!$B:$B,0)),IFERROR(INDEX('Mr Manu Vikraman'!O:O,MATCH($B112,'Mr Manu Vikraman'!$B:$B,0)),""))} | P112: {=IFERROR(INDEX('Mr Sandeep Kumar'!P:P,MATCH($B112,'Mr Sandeep Kumar'!$B:$B,0)),IFERROR(INDEX('Mr Manu Vikraman'!P:P,MATCH($B112,'Mr Manu Vikraman'!$B:$B,0)),""))} | Q112: =IFERROR(SUM(G112:P112),0) -> 0 | R112: =IFERROR(Q112/IF(COUNTIF(G112:P112,">0")=0,1,COUNTIF(G112:P112,">0")),0) -> 0 | S112: =IF(R112>=9,"A+",IF(R112>=8,"A",IF(R112>=7,"B+",IF(R112>=6,"B",IF(R112>=5,"C","D"))))) -> D | T112: =IF(COUNTIF(G112:P112,">0")=10,"Completed",IF(COUNTIF(G112:P112,">0")>=5,"In Progress",IF(COUNTIF(G112:P112,">0")>0,"Started","Not Started"))) -> Not Started
A113: 107 | B113: 26PGDMFM003 | C113: 28-Aditi.Pandey@fiib.edu.in | D113: Aditi Pandey | G113: {=IFERROR(INDEX('Mr Sandeep Kumar'!G:G,MATCH($B113,'Mr Sandeep Kumar'!$B:$B,0)),IFERROR(INDEX('Mr Manu Vikraman'!G:G,MATCH($B113,'Mr Manu Vikraman'!$B:$B,0)),""))} | H113: {=IFERROR(INDEX('Mr Sandeep Kumar'!H:H,MATCH($B113,'Mr Sandeep Kumar'!$B:$B,0)),IFERROR(INDEX('Mr Manu Vikraman'!H:H,MATCH($B113,'Mr Manu Vikraman'!$B:$B,0)),""))} | I113: {=IFERROR(INDEX('Mr Sandeep Kumar'!I:I,MATCH($B113,'Mr Sandeep Kumar'!$B:$B,0)),IFERROR(INDEX('Mr Manu Vikraman'!I:I,MATCH($B113,'Mr Manu Vikraman'!$B:$B,0)),""))} | J113: {=IFERROR(INDEX('Mr Sandeep Kumar'!J:J,MATCH($B113,'Mr Sandeep Kumar'!$B:$B,0)),IFERROR(INDEX('Mr Manu Vikraman'!J:J,MATCH($B113,'Mr Manu Vikraman'!$B:$B,0)),""))} | K113: {=IFERROR(INDEX('Mr Sandeep Kumar'!K:K,MATCH($B113,'Mr Sandeep Kumar'!$B:$B,0)),IFERROR(INDEX('Mr Manu Vikraman'!K:K,MATCH($B113,'Mr Manu Vikraman'!$B:$B,0)),""))} | L113: {=IFERROR(INDEX('Mr Sandeep Kumar'!L:L,MATCH($B113,'Mr Sandeep Kumar'!$B:$B,0)),IFERROR(INDEX('Mr Manu Vikraman'!L:L,MATCH($B113,'Mr Manu Vikraman'!$B:$B,0)),""))} | M113: {=IFERROR(INDEX('Mr Sandeep Kumar'!M:M,MATCH($B113,'Mr Sandeep Kumar'!$B:$B,0)),IFERROR(INDEX('Mr Manu Vikraman'!M:M,MATCH($B113,'Mr Manu Vikraman'!$B:$B,0)),""))} | N113: {=IFERROR(INDEX('Mr Sandeep Kumar'!N:N,MATCH($B113,'Mr Sandeep Kumar'!$B:$B,0)),IFERROR(INDEX('Mr Manu Vikraman'!N:N,MATCH($B113,'Mr Manu Vikraman'!$B:$B,0)),""))} | O113: {=IFERROR(INDEX('Mr Sandeep Kumar'!O:O,MATCH($B113,'Mr Sandeep Kumar'!$B:$B,0)),IFERROR(INDEX('Mr Manu Vikraman'!O:O,MATCH($B113,'Mr Manu Vikraman'!$B:$B,0)),""))} | P113: {=IFERROR(INDEX('Mr Sandeep Kumar'!P:P,MATCH($B113,'Mr Sandeep Kumar'!$B:$B,0)),IFERROR(INDEX('Mr Manu Vikraman'!P:P,MATCH($B113,'Mr Manu Vikraman'!$B:$B,0)),""))} | Q113: =IFERROR(SUM(G113:P113),0) -> 0 | R113: =IFERROR(Q113/IF(COUNTIF(G113:P113,">0")=0,1,COUNTIF(G113:P113,">0")),0) -> 0 | S113: =IF(R113>=9,"A+",IF(R113>=8,"A",IF(R113>=7,"B+",IF(R113>=6,"B",IF(R113>=5,"C","D"))))) -> D | T113: =IF(COUNTIF(G113:P113,">0")=10,"Completed",IF(COUNTIF(G113:P113,">0")>=5,"In Progress",IF(COUNTIF(G113:P113,">0")>0,"Started","Not Started"))) -> Not Started
A114: 108 | B114: 26PGDMFM004 | C114: 28-Aditi.Singh@fiib.edu.in | D114: Aditi Singh | G114: {=IFERROR(INDEX('Mr Sandeep Kumar'!G:G,MATCH($B114,'Mr Sandeep Kumar'!$B:$B,0)),IFERROR(INDEX('Mr Manu Vikraman'!G:G,MATCH($B114,'Mr Manu Vikraman'!$B:$B,0)),""))} | H114: {=IFERROR(INDEX('Mr Sandeep Kumar'!H:H,MATCH($B114,'Mr Sandeep Kumar'!$B:$B,0)),IFERROR(INDEX('Mr Manu Vikraman'!H:H,MATCH($B114,'Mr Manu Vikraman'!$B:$B,0)),""))} | I114: {=IFERROR(INDEX('Mr Sandeep Kumar'!I:I,MATCH($B114,'Mr Sandeep Kumar'!$B:$B,0)),IFERROR(INDEX('Mr Manu Vikraman'!I:I,MATCH($B114,'Mr Manu Vikraman'!$B:$B,0)),""))} | J114: {=IFERROR(INDEX('Mr Sandeep Kumar'!J:J,MATCH($B114,'Mr Sandeep Kumar'!$B:$B,0)),IFERROR(INDEX('Mr Manu Vikraman'!J:J,MATCH($B114,'Mr Manu Vikraman'!$B:$B,0)),""))} | K114: {=IFERROR(INDEX('Mr Sandeep Kumar'!K:K,MATCH($B114,'Mr Sandeep Kumar'!$B:$B,0)),IFERROR(INDEX('Mr Manu Vikraman'!K:K,MATCH($B114,'Mr Manu Vikraman'!$B:$B,0)),""))} | L114: {=IFERROR(INDEX('Mr Sandeep Kumar'!L:L,MATCH($B114,'Mr Sandeep Kumar'!$B:$B,0)),IFERROR(INDEX('Mr Manu Vikraman'!L:L,MATCH($B114,'Mr Manu Vikraman'!$B:$B,0)),""))} | M114: {=IFERROR(INDEX('Mr Sandeep Kumar'!M:M,MATCH($B114,'Mr Sandeep Kumar'!$B:$B,0)),IFERROR(INDEX('Mr Manu Vikraman'!M:M,MATCH($B114,'Mr Manu Vikraman'!$B:$B,0)),""))} | N114: {=IFERROR(INDEX('Mr Sandeep Kumar'!N:N,MATCH($B114,'Mr Sandeep Kumar'!$B:$B,0)),IFERROR(INDEX('Mr Manu Vikraman'!N:N,MATCH($B114,'Mr Manu Vikraman'!$B:$B,0)),""))} | O114: {=IFERROR(INDEX('Mr Sandeep Kumar'!O:O,MATCH($B114,'Mr Sandeep Kumar'!$B:$B,0)),IFERROR(INDEX('Mr Manu Vikraman'!O:O,MATCH($B114,'Mr Manu Vikraman'!$B:$B,0)),""))} | P114: {=IFERROR(INDEX('Mr Sandeep Kumar'!P:P,MATCH($B114,'Mr Sandeep Kumar'!$B:$B,0)),IFERROR(INDEX('Mr Manu Vikraman'!P:P,MATCH($B114,'Mr Manu Vikraman'!$B:$B,0)),""))} | Q114: =IFERROR(SUM(G114:P114),0) -> 0 | R114: =IFERROR(Q114/IF(COUNTIF(G114:P114,">0")=0,1,COUNTIF(G114:P114,">0")),0) -> 0 | S114: =IF(R114>=9,"A+",IF(R114>=8,"A",IF(R114>=7,"B+",IF(R114>=6,"B",IF(R114>=5,"C","D"))))) -> D | T114: =IF(COUNTIF(G114:P114,">0")=10,"Completed",IF(COUNTIF(G114:P114,">0")>=5,"In Progress",IF(COUNTIF(G114:P114,">0")>0,"Started","Not Started"))) -> Not Started
A115: 109 | B115: 26PGDMFM005 | C115: 28-alka.mehta@fiib.edu.in | D115: Alka Mehta | G115: {=IFERROR(INDEX('Mr Sandeep Kumar'!G:G,MATCH($B115,'Mr Sandeep Kumar'!$B:$B,0)),IFERROR(INDEX('Mr Manu Vikraman'!G:G,MATCH($B115,'Mr Manu Vikraman'!$B:$B,0)),""))} | H115: {=IFERROR(INDEX('Mr Sandeep Kumar'!H:H,MATCH($B115,'Mr Sandeep Kumar'!$B:$B,0)),IFERROR(INDEX('Mr Manu Vikraman'!H:H,MATCH($B115,'Mr Manu Vikraman'!$B:$B,0)),""))} | I115: {=IFERROR(INDEX('Mr Sandeep Kumar'!I:I,MATCH($B115,'Mr Sandeep Kumar'!$B:$B,0)),IFERROR(INDEX('Mr Manu Vikraman'!I:I,MATCH($B115,'Mr Manu Vikraman'!$B:$B,0)),""))} | J115: {=IFERROR(INDEX('Mr Sandeep Kumar'!J:J,MATCH($B115,'Mr Sandeep Kumar'!$B:$B,0)),IFERROR(INDEX('Mr Manu Vikraman'!J:J,MATCH($B115,'Mr Manu Vikraman'!$B:$B,0)),""))} | K115: {=IFERROR(INDEX('Mr Sandeep Kumar'!K:K,MATCH($B115,'Mr Sandeep Kumar'!$B:$B,0)),IFERROR(INDEX('Mr Manu Vikraman'!K:K,MATCH($B115,'Mr Manu Vikraman'!$B:$B,0)),""))} | L115: {=IFERROR(INDEX('Mr Sandeep Kumar'!L:L,MATCH($B115,'Mr Sandeep Kumar'!$B:$B,0)),IFERROR(INDEX('Mr Manu Vikraman'!L:L,MATCH($B115,'Mr Manu Vikraman'!$B:$B,0)),""))} | M115: {=IFERROR(INDEX('Mr Sandeep Kumar'!M:M,MATCH($B115,'Mr Sandeep Kumar'!$B:$B,0)),IFERROR(INDEX('Mr Manu Vikraman'!M:M,MATCH($B115,'Mr Manu Vikraman'!$B:$B,0)),""))} | N115: {=IFERROR(INDEX('Mr Sandeep Kumar'!N:N,MATCH($B115,'Mr Sandeep Kumar'!$B:$B,0)),IFERROR(INDEX('Mr Manu Vikraman'!N:N,MATCH($B115,'Mr Manu Vikraman'!$B:$B,0)),""))} | O115: {=IFERROR(INDEX('Mr Sandeep Kumar'!O:O,MATCH($B115,'Mr Sandeep Kumar'!$B:$B,0)),IFERROR(INDEX('Mr Manu Vikraman'!O:O,MATCH($B115,'Mr Manu Vikraman'!$B:$B,0)),""))} | P115: {=IFERROR(INDEX('Mr Sandeep Kumar'!P:P,MATCH($B115,'Mr Sandeep Kumar'!$B:$B,0)),IFERROR(INDEX('Mr Manu Vikraman'!P:P,MATCH($B115,'Mr Manu Vikraman'!$B:$B,0)),""))} | Q115: =IFERROR(SUM(G115:P115),0) -> 0 | R115: =IFERROR(Q115/IF(COUNTIF(G115:P115,">0")=0,1,COUNTIF(G115:P115,">0")),0) -> 0 | S115: =IF(R115>=9,"A+",IF(R115>=8,"A",IF(R115>=7,"B+",IF(R115>=6,"B",IF(R115>=5,"C","D"))))) -> D | T115: =IF(COUNTIF(G115:P115,">0")=10,"Completed",IF(COUNTIF(G115:P115,">0")>=5,"In Progress",IF(COUNTIF(G115:P115,">0")>0,"Started","Not Started"))) -> Not Started
A116: 110 | B116: 26PGDMFM006 | C116: 28-Anand.Mohapatra@fiib.edu.in | D116: Anand Mohapatra | G116: {=IFERROR(INDEX('Mr Sandeep Kumar'!G:G,MATCH($B116,'Mr Sandeep Kumar'!$B:$B,0)),IFERROR(INDEX('Mr Manu Vikraman'!G:G,MATCH($B116,'Mr Manu Vikraman'!$B:$B,0)),""))} | H116: {=IFERROR(INDEX('Mr Sandeep Kumar'!H:H,MATCH($B116,'Mr Sandeep Kumar'!$B:$B,0)),IFERROR(INDEX('Mr Manu Vikraman'!H:H,MATCH($B116,'Mr Manu Vikraman'!$B:$B,0)),""))} | I116: {=IFERROR(INDEX('Mr Sandeep Kumar'!I:I,MATCH($B116,'Mr Sandeep Kumar'!$B:$B,0)),IFERROR(INDEX('Mr Manu Vikraman'!I:I,MATCH($B116,'Mr Manu Vikraman'!$B:$B,0)),""))} | J116: {=IFERROR(INDEX('Mr Sandeep Kumar'!J:J,MATCH($B116,'Mr Sandeep Kumar'!$B:$B,0)),IFERROR(INDEX('Mr Manu Vikraman'!J:J,MATCH($B116,'Mr Manu Vikraman'!$B:$B,0)),""))} | K116: {=IFERROR(INDEX('Mr Sandeep Kumar'!K:K,MATCH($B116,'Mr Sandeep Kumar'!$B:$B,0)),IFERROR(INDEX('Mr Manu Vikraman'!K:K,MATCH($B116,'Mr Manu Vikraman'!$B:$B,0)),""))} | L116: {=IFERROR(INDEX('Mr Sandeep Kumar'!L:L,MATCH($B116,'Mr Sandeep Kumar'!$B:$B,0)),IFERROR(INDEX('Mr Manu Vikraman'!L:L,MATCH($B116,'Mr Manu Vikraman'!$B:$B,0)),""))} | M116: {=IFERROR(INDEX('Mr Sandeep Kumar'!M:M,MATCH($B116,'Mr Sandeep Kumar'!$B:$B,0)),IFERROR(INDEX('Mr Manu Vikraman'!M:M,MATCH($B116,'Mr Manu Vikraman'!$B:$B,0)),""))} | N116: {=IFERROR(INDEX('Mr Sandeep Kumar'!N:N,MATCH($B116,'Mr Sandeep Kumar'!$B:$B,0)),IFERROR(INDEX('Mr Manu Vikraman'!N:N,MATCH($B116,'Mr Manu Vikraman'!$B:$B,0)),""))} | O116: {=IFERROR(INDEX('Mr Sandeep Kumar'!O:O,MATCH($B116,'Mr Sandeep Kumar'!$B:$B,0)),IFERROR(INDEX('Mr Manu Vikraman'!O:O,MATCH($B116,'Mr Manu Vikraman'!$B:$B,0)),""))} | P116: {=IFERROR(INDEX('Mr Sandeep Kumar'!P:P,MATCH($B116,'Mr Sandeep Kumar'!$B:$B,0)),IFERROR(INDEX('Mr Manu Vikraman'!P:P,MATCH($B116,'Mr Manu Vikraman'!$B:$B,0)),""))} | Q116: =IFERROR(SUM(G116:P116),0) -> 0 | R116: =IFERROR(Q116/IF(COUNTIF(G116:P116,">0")=0,1,COUNTIF(G116:P116,">0")),0) -> 0 | S116: =IF(R116>=9,"A+",IF(R116>=8,"A",IF(R116>=7,"B+",IF(R116>=6,"B",IF(R116>=5,"C","D"))))) -> D | T116: =IF(COUNTIF(G116:P116,">0")=10,"Completed",IF(COUNTIF(G116:P116,">0")>=5,"In Progress",IF(COUNTIF(G116:P116,">0")>0,"Started","Not Started"))) -> Not Started
A117: 111 | B117: 26PGDMFM007 | C117: 28-Anuj.Nautiyal@fiib.edu.in | D117: Anuj Nautiyal | G117: {=IFERROR(INDEX('Mr Sandeep Kumar'!G:G,MATCH($B117,'Mr Sandeep Kumar'!$B:$B,0)),IFERROR(INDEX('Mr Manu Vikraman'!G:G,MATCH($B117,'Mr Manu Vikraman'!$B:$B,0)),""))} | H117: {=IFERROR(INDEX('Mr Sandeep Kumar'!H:H,MATCH($B117,'Mr Sandeep Kumar'!$B:$B,0)),IFERROR(INDEX('Mr Manu Vikraman'!H:H,MATCH($B117,'Mr Manu Vikraman'!$B:$B,0)),""))} | I117: {=IFERROR(INDEX('Mr Sandeep Kumar'!I:I,MATCH($B117,'Mr Sandeep Kumar'!$B:$B,0)),IFERROR(INDEX('Mr Manu Vikraman'!I:I,MATCH($B117,'Mr Manu Vikraman'!$B:$B,0)),""))} | J117: {=IFERROR(INDEX('Mr Sandeep Kumar'!J:J,MATCH($B117,'Mr Sandeep Kumar'!$B:$B,0)),IFERROR(INDEX('Mr Manu Vikraman'!J:J,MATCH($B117,'Mr Manu Vikraman'!$B:$B,0)),""))} | K117: {=IFERROR(INDEX('Mr Sandeep Kumar'!K:K,MATCH($B117,'Mr Sandeep Kumar'!$B:$B,0)),IFERROR(INDEX('Mr Manu Vikraman'!K:K,MATCH($B117,'Mr Manu Vikraman'!$B:$B,0)),""))} | L117: {=IFERROR(INDEX('Mr Sandeep Kumar'!L:L,MATCH($B117,'Mr Sandeep Kumar'!$B:$B,0)),IFERROR(INDEX('Mr Manu Vikraman'!L:L,MATCH($B117,'Mr Manu Vikraman'!$B:$B,0)),""))} | M117: {=IFERROR(INDEX('Mr Sandeep Kumar'!M:M,MATCH($B117,'Mr Sandeep Kumar'!$B:$B,0)),IFERROR(INDEX('Mr Manu Vikraman'!M:M,MATCH($B117,'Mr Manu Vikraman'!$B:$B,0)),""))} | N117: {=IFERROR(INDEX('Mr Sandeep Kumar'!N:N,MATCH($B117,'Mr Sandeep Kumar'!$B:$B,0)),IFERROR(INDEX('Mr Manu Vikraman'!N:N,MATCH($B117,'Mr Manu Vikraman'!$B:$B,0)),""))} | O117: {=IFERROR(INDEX('Mr Sandeep Kumar'!O:O,MATCH($B117,'Mr Sandeep Kumar'!$B:$B,0)),IFERROR(INDEX('Mr Manu Vikraman'!O:O,MATCH($B117,'Mr Manu Vikraman'!$B:$B,0)),""))} | P117: {=IFERROR(INDEX('Mr Sandeep Kumar'!P:P,MATCH($B117,'Mr Sandeep Kumar'!$B:$B,0)),IFERROR(INDEX('Mr Manu Vikraman'!P:P,MATCH($B117,'Mr Manu Vikraman'!$B:$B,0)),""))} | Q117: =IFERROR(SUM(G117:P117),0) -> 0 | R117: =IFERROR(Q117/IF(COUNTIF(G117:P117,">0")=0,1,COUNTIF(G117:P117,">0")),0) -> 0 | S117: =IF(R117>=9,"A+",IF(R117>=8,"A",IF(R117>=7,"B+",IF(R117>=6,"B",IF(R117>=5,"C","D"))))) -> D | T117: =IF(COUNTIF(G117:P117,">0")=10,"Completed",IF(COUNTIF(G117:P117,">0")>=5,"In Progress",IF(COUNTIF(G117:P117,">0")>0,"Started","Not Started"))) -> Not Started
A118: 112 | B118: 26PGDMFM008 | C118: 28-Arav.Singh@fiib.edu.in | D118: Arav Singh | G118: {=IFERROR(INDEX('Mr Sandeep Kumar'!G:G,MATCH($B118,'Mr Sandeep Kumar'!$B:$B,0)),IFERROR(INDEX('Mr Manu Vikraman'!G:G,MATCH($B118,'Mr Manu Vikraman'!$B:$B,0)),""))} | H118: {=IFERROR(INDEX('Mr Sandeep Kumar'!H:H,MATCH($B118,'Mr Sandeep Kumar'!$B:$B,0)),IFERROR(INDEX('Mr Manu Vikraman'!H:H,MATCH($B118,'Mr Manu Vikraman'!$B:$B,0)),""))} | I118: {=IFERROR(INDEX('Mr Sandeep Kumar'!I:I,MATCH($B118,'Mr Sandeep Kumar'!$B:$B,0)),IFERROR(INDEX('Mr Manu Vikraman'!I:I,MATCH($B118,'Mr Manu Vikraman'!$B:$B,0)),""))} | J118: {=IFERROR(INDEX('Mr Sandeep Kumar'!J:J,MATCH($B118,'Mr Sandeep Kumar'!$B:$B,0)),IFERROR(INDEX('Mr Manu Vikraman'!J:J,MATCH($B118,'Mr Manu Vikraman'!$B:$B,0)),""))} | K118: {=IFERROR(INDEX('Mr Sandeep Kumar'!K:K,MATCH($B118,'Mr Sandeep Kumar'!$B:$B,0)),IFERROR(INDEX('Mr Manu Vikraman'!K:K,MATCH($B118,'Mr Manu Vikraman'!$B:$B,0)),""))} | L118: {=IFERROR(INDEX('Mr Sandeep Kumar'!L:L,MATCH($B118,'Mr Sandeep Kumar'!$B:$B,0)),IFERROR(INDEX('Mr Manu Vikraman'!L:L,MATCH($B118,'Mr Manu Vikraman'!$B:$B,0)),""))} | M118: {=IFERROR(INDEX('Mr Sandeep Kumar'!M:M,MATCH($B118,'Mr Sandeep Kumar'!$B:$B,0)),IFERROR(INDEX('Mr Manu Vikraman'!M:M,MATCH($B118,'Mr Manu Vikraman'!$B:$B,0)),""))} | N118: {=IFERROR(INDEX('Mr Sandeep Kumar'!N:N,MATCH($B118,'Mr Sandeep Kumar'!$B:$B,0)),IFERROR(INDEX('Mr Manu Vikraman'!N:N,MATCH($B118,'Mr Manu Vikraman'!$B:$B,0)),""))} | O118: {=IFERROR(INDEX('Mr Sandeep Kumar'!O:O,MATCH($B118,'Mr Sandeep Kumar'!$B:$B,0)),IFERROR(INDEX('Mr Manu Vikraman'!O:O,MATCH($B118,'Mr Manu Vikraman'!$B:$B,0)),""))} | P118: {=IFERROR(INDEX('Mr Sandeep Kumar'!P:P,MATCH($B118,'Mr Sandeep Kumar'!$B:$B,0)),IFERROR(INDEX('Mr Manu Vikraman'!P:P,MATCH($B118,'Mr Manu Vikraman'!$B:$B,0)),""))} | Q118: =IFERROR(SUM(G118:P118),0) -> 0 | R118: =IFERROR(Q118/IF(COUNTIF(G118:P118,">0")=0,1,COUNTIF(G118:P118,">0")),0) -> 0 | S118: =IF(R118>=9,"A+",IF(R118>=8,"A",IF(R118>=7,"B+",IF(R118>=6,"B",IF(R118>=5,"C","D"))))) -> D | T118: =IF(COUNTIF(G118:P118,">0")=10,"Completed",IF(COUNTIF(G118:P118,">0")>=5,"In Progress",IF(COUNTIF(G118:P118,">0")>0,"Started","Not Started"))) -> Not Started
